Workbook

Sheet 1. Data Mentah
A1: Data Lowongan & Profil Pelamar
A3: ID | B3: Kategori Posisi | C3: Teks Asli
A4: L1 | B4: Web Developer | C4: Dicari Web Developer yang menguasai pemrograman PHP, framework Laravel, database MySQL, dan pembuatan REST API.
A5: L2 | B5: Data Scientist | C5: Perusahaan membutuhkan Data Scientist ahli Python, SQL, algoritma Machine Learning, dan analisis statistik data.
A6: L3 | B6: UI/UX Designer | C6: Mencari UI/UX Designer untuk membuat prototyping, wireframing, riset pengguna, dan mahir menggunakan Figma.
A7: L4 | B7: Graphic Designer | C7: Dibutuhkan Graphic Designer kreatif yang menguasai Adobe Photoshop, Illustrator, desain kreatif, dan branding.
A8: L5 | B8: Akuntan Pajak | C8: Mencari Akuntan Pajak berpengalaman mengelola laporan keuangan, rekonsiliasi bank, pajak perusahaan, dan Microsoft Excel.
A9: P1 | B9: Budi Santoso | C9: Saya Web Developer berpengalaman menggunakan PHP, framework Laravel, database MySQL, dan terbiasa membuat REST API.
A10: P2 | B10: Andi Wijaya | C10: Fullstack developer yang menguasai pemrograman PHP dan MySQL, namun juga bisa menggunakan Adobe Photoshop untuk desain banner web.
A11: P3 | B11: Citra Dewi | C11: Lulusan Statistika yang fokus sebagai Data Scientist. Mahir Python, SQL, dan pemodelan Machine Learning untuk analisis data.
A12: P4 | B12: Deni Setiawan | C12: Data analyst yang terbiasa melakukan query dengan SQL dan database MySQL. Sedikit paham Python tapi belum belajar Machine Learning.
A13: P5 | B13: Eko Prasetyo | C13: UI/UX Designer spesialis produk digital. Sangat mahir menggunakan Figma untuk wireframing, prototyping, dan riset pengguna.
A14: P6 | B14: Fitriani | C14: Desainer serbabisa yang menguasai Figma untuk desain UI dan juga terbiasa menggunakan Adobe Illustrator untuk membuat aset grafis.
... A18: P10 | B18: Joko Susilo | C18: Lulusan baru administrasi perkantoran yang menguasai Microsoft Excel untuk input data logistik, belum punya pengalaman akuntansi.

Sheet 2. Preprocessing
A1: Tahapan Text Preprocessing (Sastrawi Simulation)
A3: ID | B3: 1. Teks Asli | C3: 2. Tokenization | D3: 3. Stopword & Stemming
A4: L1 | B4: Dicari Web Developer yang menguasai pemrograman PHP, framework Laravel, database MySQL, dan pembuatan REST API. | C4: dicari web developer yang menguasai pemrograman php framework laravel database mysql dan pembuatan rest api | D4: cari web developer kuasa program php framework laravel database mysql buat rest api
A5: L2 | B5: Perusahaan membutuhkan Data Scientist ahli Python, SQL, algoritma Machine Learning, dan analisis statistik data. | C5: perusahaan membutuhkan data scientist ahli python sql algoritma machine learning dan analisis statistik data | D5: perusahaan butuh data scientist ahli python sql algoritma machine learning analisis statistik data
A6: L3 | B6: Mencari UI/UX Designer untuk membuat prototyping, wireframing, riset pengguna, dan mahir menggunakan Figma. | C6: mencari ui ux designer untuk membuat prototyping wireframing riset pengguna dan mahir menggunakan figma | D6: cari ui ux designer buat prototyping wireframing riset guna mahir guna figma
A7: L4 | B7: Dibutuhkan Graphic Designer kreatif yang menguasai Adobe Photoshop, Illustrator, desain kreatif, dan branding. | C7: dibutuhkan graphic designer kreatif yang menguasai adobe photoshop illustrator desain kreatif dan branding | D7: butuh graphic designer kreatif kuasa adobe photoshop illustrator desain kreatif branding
A8: L5 | B8: Mencari Akuntan Pajak berpengalaman mengelola laporan keuangan, rekonsiliasi bank, pajak perusahaan, dan Microsoft Excel. | C8: mencari akuntan pajak berpengalaman mengelola laporan keuangan rekonsiliasi bank pajak perusahaan dan microsoft excel | D8: cari akuntan pajak alam kelola lapor uang rekonsiliasi bank pajak perusahaan microsoft excel
A9: P1 | B9: Saya Web Developer berpengalaman menggunakan PHP, framework Laravel, database MySQL, dan terbiasa membuat REST API. | C9: saya web developer berpengalaman menggunakan php framework laravel database mysql dan terbiasa membuat rest api | D9: web developer alam guna php framework laravel database mysql biasa buat rest api
A10: P2 | B10: Fullstack developer yang menguasai pemrograman PHP dan MySQL, namun juga bisa menggunakan Adobe Photoshop untuk desain banner web. | C10: fullstack developer yang menguasai pemrograman php dan mysql namun juga bisa menggunakan adobe photoshop untuk desain banner web | D10: fullstack developer kuasa program php mysql guna adobe photoshop desain banner web
A11: P3 | B11: Lulusan Statistika yang fokus sebagai Data Scientist. Mahir Python, SQL, dan pemodelan Machine Learning untuk analisis data. | C11: lulusan statistika yang fokus sebagai data scientist mahir python sql dan pemodelan machine learning untuk analisis data | D11: lulus statistika fokus data scientist mahir python sql model machine learning analisis data
A12: P4 | B12: Data analyst yang terbiasa melakukan query dengan SQL dan database MySQL. Sedikit paham Python tapi belum belajar Machine Learning. | C12: data analyst yang terbiasa melakukan query dengan sql dan database mysql sedikit paham python tapi belum belajar machine learning | D12: data analyst biasa laku query sql database mysql sedikit paham python ajar machine learning
A13: P5 | B13: UI/UX Designer spesialis produk digital. Sangat mahir menggunakan Figma untuk wireframing, prototyping, dan riset pengguna. | C13: ui ux designer spesialis produk digital sangat mahir menggunakan figma untuk wireframing prototyping dan riset pengguna | D13: ui ux designer spesialis produk digital sangat mahir guna figma wireframing prototyping riset guna
A14: P6 | B14: Desainer serbabisa yang menguasai Figma untuk desain UI dan juga terbiasa menggunakan Adobe Illustrator untuk membuat aset grafis. | C14: desainer serbabisa yang menguasai figma untuk desain ui dan juga terbiasa menggunakan adobe illustrator untuk membuat aset grafis | D14: desain serbabisa kuasa figma desain ui biasa guna adobe illustrator buat aset grafis
... A18: P10 | B18: Lulusan baru administrasi perkantoran yang menguasai Microsoft Excel untuk input data logistik, belum punya pengalaman akuntansi. | C18: lulusan baru administrasi perkantoran yang menguasai microsoft excel untuk input data logistik belum punya pengalaman akuntansi | D18: lulus baru administrasi kantor kuasa microsoft excel input data logistik punya alam akuntansi

Sheet 3. Term Frequency (TF)
A1: Matriks Jumlah Kata (Term Frequency)
A3: Term | B3: DF (Doc Freq) | C3: L1 | D3: L2 | E3: L3 | F3: L4 | G3: L5 | H3: P1 | I3: P2 | J3: P3 | K3: P4 | L3: P5 | M3: P6 | N3: P7 | O3: P8 | P3: P9 | Q3: P10
A4: administrasi | B4: 1 | C4: 0 | D4: 0 | E4: 0 | F4: 0 | G4: 0 | H4: 0 | I4: 0 | J4: 0 | K4: 0 | L4: 0 | M4: 0 | N4: 0 | O4: 0 | P4: 0 | Q4: 1
A5: adobe | B5: 4 | C5: 0 | D5: 0 | E5: 0 | F5: 1 | G5: 0 | H5: 0 | I5: 1 | J5: 0 | K5: 0 | L5: 0 | M5: 1 | N5: 1 | O5: 0 | P5: 0 | Q5: 0
A6: ahli | B6: 2 | C6: 0 | D6: 1 | E6: 0 | F6: 0 | G6: 0 | H6: 0 | I6: 0 | J6: 0 | K6: 0 | L6: 0 | M6: 0 | N6: 0 | O6: 1 | P6: 0 | Q6: 0
A7: ajar | B7: 1 | C7: 0 | D7: 0 | E7: 0 | F7: 0 | G7: 0 | H7: 0 | I7: 0 | J7: 0 | K7: 1 | L7: 0 | M7: 0 | N7: 0 | O7: 0 | P7: 0 | Q7: 0
A8: akuntan | B8: 2 | C8: 0 | D8: 0 | E8: 0 | F8: 0 | G8: 1 | H8: 0 | I8: 0 | J8: 0 | K8: 0 | L8: 0 | M8: 0 | N8: 0 | O8: 1 | P8: 0 | Q8: 0
A9: akuntansi | B9: 1 | C9: 0 | D9: 0 | E9: 0 | F9: 0 | G9: 0 | H9: 0 | I9: 0 | J9: 0 | K9: 0 | L9: 0 | M9: 0 | N9: 0 | O9: 0 | P9: 0 | Q9: 1
A10: alam | B10: 3 | C10: 0 | D10: 0 | E10: 0 | F10: 0 | G10: 1 | H10: 1 | I10: 0 | J10: 0 | K10: 0 | L10: 0 | M10: 0 | N10: 0 | O10: 0 | P10: 0 | Q10: 1
A11: algoritma | B11: 1 | C11: 0 | D11: 1 | E11: 0 | F11: 0 | G11: 0 | H11: 0 | I11: 0 | J11: 0 | K11: 0 | L11: 0 | M11: 0 | N11: 0 | O11: 0 | P11: 0 | Q11: 0
A12: analisis | B12: 2 | C12: 0 | D12: 1 | E12: 0 | F12: 0 | G12: 0 | H12: 0 | I12: 0 | J12: 1 | K12: 0 | L12: 0 | M12: 0 | N12: 0 | O12: 0 | P12: 0 | Q12: 0
A13: analyst | B13: 1 | C13: 0 | D13: 0 | E13: 0 | F13: 0 | G13: 0 | H13: 0 | I13: 0 | J13: 0 | K13: 1 | L13: 0 | M13: 0 | N13: 0 | O13: 0 | P13: 0 | Q13: 0
A14: api | B14: 2 | C14: 1 | D14: 0 | E14: 0 | F14: 0 | G14: 0 | H14: 1 | I14: 0 | J14: 0 | K14: 0 | L14: 0 | M14: 0 | N14: 0 | O14: 0 | P14: 0 | Q14: 0
A15: aset | B15: 1 | C15: 0 | D15: 0 | E15: 0 | F15: 0 | G15: 0 | H15: 0 | I15: 0 | J15: 0 | K15: 0 | L15: 0 | M15: 1 | N15: 0 | O15: 0 | P15: 0 | Q15: 0
... A93: wireframing | B93: 2 | C93: 0 | D93: 0 | E93: 1 | F93: 0 | G93: 0 | H93: 0 | I93: 0 | J93: 0 | K93: 0 | L93: 1 | M93: 0 | N93: 0 | O93: 0 | P93: 0 | Q93: 0

Sheet 4. TF-IDF
A1: Matriks Pembobotan Akhir (TF * IDF)
A3: Term | B3: IDF (Sklearn Math) | C3: L1 | D3: L2 | E3: L3 | F3: L4 | G3: L5 | H3: P1 | I3: P2 | J3: P3 | K3: P4 | L3: P5 | M3: P6 | N3: P7 | O3: P8 | P3: P9 | Q3: P10
A4: administrasi | B4: =LN((15+1)/('3. Term Frequency (TF)'!B4+1))+1 | C4: ='3. Term Frequency (TF)'!C4 * $B4 | D4: ='3. Term Frequency (TF)'!D4 * $B4 | E4: ='3. Term Frequency (TF)'!E4 * $B4 | F4: ='3. Term Frequency (TF)'!F4 * $B4 | G4: ='3. Term Frequency (TF)'!G4 * $B4 | H4: ='3. Term Frequency (TF)'!H4 * $B4 | I4: ='3. Term Frequency (TF)'!I4 * $B4 | J4: ='3. Term Frequency (TF)'!J4 * $B4 | ... Q4: ='3. Term Frequency (TF)'!Q4 * $B4
A5: adobe | B5: =LN((15+1)/('3. Term Frequency (TF)'!B5+1))+1 | C5: ='3. Term Frequency (TF)'!C5 * $B5 | D5: ='3. Term Frequency (TF)'!D5 * $B5 | E5: ='3. Term Frequency (TF)'!E5 * $B5 | F5: ='3. Term Frequency (TF)'!F5 * $B5 | G5: ='3. Term Frequency (TF)'!G5 * $B5 | H5: ='3. Term Frequency (TF)'!H5 * $B5 | I5: ='3. Term Frequency (TF)'!I5 * $B5 | J5: ='3. Term Frequency (TF)'!J5 * $B5 | ... Q5: ='3. Term Frequency (TF)'!Q5 * $B5
A6: ahli | B6: =LN((15+1)/('3. Term Frequency (TF)'!B6+1))+1 | C6: ='3. Term Frequency (TF)'!C6 * $B6 | D6: ='3. Term Frequency (TF)'!D6 * $B6 | E6: ='3. Term Frequency (TF)'!E6 * $B6 | F6: ='3. Term Frequency (TF)'!F6 * $B6 | G6: ='3. Term Frequency (TF)'!G6 * $B6 | H6: ='3. Term Frequency (TF)'!H6 * $B6 | I6: ='3. Term Frequency (TF)'!I6 * $B6 | J6: ='3. Term Frequency (TF)'!J6 * $B6 | ... Q6: ='3. Term Frequency (TF)'!Q6 * $B6
A7: ajar | B7: =LN((15+1)/('3. Term Frequency (TF)'!B7+1))+1 | C7: ='3. Term Frequency (TF)'!C7 * $B7 | D7: ='3. Term Frequency (TF)'!D7 * $B7 | E7: ='3. Term Frequency (TF)'!E7 * $B7 | F7: ='3. Term Frequency (TF)'!F7 * $B7 | G7: ='3. Term Frequency (TF)'!G7 * $B7 | H7: ='3. Term Frequency (TF)'!H7 * $B7 | I7: ='3. Term Frequency (TF)'!I7 * $B7 | J7: ='3. Term Frequency (TF)'!J7 * $B7 | ... Q7: ='3. Term Frequency (TF)'!Q7 * $B7
A8: akuntan | B8: =LN((15+1)/('3. Term Frequency (TF)'!B8+1))+1 | C8: ='3. Term Frequency (TF)'!C8 * $B8 | D8: ='3. Term Frequency (TF)'!D8 * $B8 | E8: ='3. Term Frequency (TF)'!E8 * $B8 | F8: ='3. Term Frequency (TF)'!F8 * $B8 | G8: ='3. Term Frequency (TF)'!G8 * $B8 | H8: ='3. Term Frequency (TF)'!H8 * $B8 | I8: ='3. Term Frequency (TF)'!I8 * $B8 | J8: ='3. Term Frequency (TF)'!J8 * $B8 | ... Q8: ='3. Term Frequency (TF)'!Q8 * $B8
A9: akuntansi | B9: =LN((15+1)/('3. Term Frequency (TF)'!B9+1))+1 | C9: ='3. Term Frequency (TF)'!C9 * $B9 | D9: ='3. Term Frequency (TF)'!D9 * $B9 | E9: ='3. Term Frequency (TF)'!E9 * $B9 | F9: ='3. Term Frequency (TF)'!F9 * $B9 | G9: ='3. Term Frequency (TF)'!G9 * $B9 | H9: ='3. Term Frequency (TF)'!H9 * $B9 | I9: ='3. Term Frequency (TF)'!I9 * $B9 | J9: ='3. Term Frequency (TF)'!J9 * $B9 | ... Q9: ='3. Term Frequency (TF)'!Q9 * $B9
A10: alam | B10: =LN((15+1)/('3. Term Frequency (TF)'!B10+1))+1 | C10: ='3. Term Frequency (TF)'!C10 * $B10 | D10: ='3. Term Frequency (TF)'!D10 * $B10 | E10: ='3. Term Frequency (TF)'!E10 * $B10 | F10: ='3. Term Frequency (TF)'!F10 * $B10 | G10: ='3. Term Frequency (TF)'!G10 * $B10 | H10: ='3. Term Frequency (TF)'!H10 * $B10 | I10: ='3. Term Frequency (TF)'!I10 * $B10 | J10: ='3. Term Frequency (TF)'!J10 * $B10 | ... Q10: ='3. Term Frequency (TF)'!Q10 * $B10
A11: algoritma | B11: =LN((15+1)/('3. Term Frequency (TF)'!B11+1))+1 | C11: ='3. Term Frequency (TF)'!C11 * $B11 | D11: ='3. Term Frequency (TF)'!D11 * $B11 | E11: ='3. Term Frequency (TF)'!E11 * $B11 | F11: ='3. Term Frequency (TF)'!F11 * $B11 | G11: ='3. Term Frequency (TF)'!G11 * $B11 | H11: ='3. Term Frequency (TF)'!H11 * $B11 | I11: ='3. Term Frequency (TF)'!I11 * $B11 | J11: ='3. Term Frequency (TF)'!J11 * $B11 | ... Q11: ='3. Term Frequency (TF)'!Q11 * $B11
A12: analisis | B12: =LN((15+1)/('3. Term Frequency (TF)'!B12+1))+1 | C12: ='3. Term Frequency (TF)'!C12 * $B12 | D12: ='3. Term Frequency (TF)'!D12 * $B12 | E12: ='3. Term Frequency (TF)'!E12 * $B12 | F12: ='3. Term Frequency (TF)'!F12 * $B12 | G12: ='3. Term Frequency (TF)'!G12 * $B12 | H12: ='3. Term Frequency (TF)'!H12 * $B12 | I12: ='3. Term Frequency (TF)'!I12 * $B12 | J12: ='3. Term Frequency (TF)'!J12 * $B12 | ... Q12: ='3. Term Frequency (TF)'!Q12 * $B12
A13: analyst | B13: =LN((15+1)/('3. Term Frequency (TF)'!B13+1))+1 | C13: ='3. Term Frequency (TF)'!C13 * $B13 | D13: ='3. Term Frequency (TF)'!D13 * $B13 | E13: ='3. Term Frequency (TF)'!E13 * $B13 | F13: ='3. Term Frequency (TF)'!F13 * $B13 | G13: ='3. Term Frequency (TF)'!G13 * $B13 | H13: ='3. Term Frequency (TF)'!H13 * $B13 | I13: ='3. Term Frequency (TF)'!I13 * $B13 | J13: ='3. Term Frequency (TF)'!J13 * $B13 | ... Q13: ='3. Term Frequency (TF)'!Q13 * $B13
A14: api | B14: =LN((15+1)/('3. Term Frequency (TF)'!B14+1))+1 | C14: ='3. Term Frequency (TF)'!C14 * $B14 | D14: ='3. Term Frequency (TF)'!D14 * $B14 | E14: ='3. Term Frequency (TF)'!E14 * $B14 | F14: ='3. Term Frequency (TF)'!F14 * $B14 | G14: ='3. Term Frequency (TF)'!G14 * $B14 | H14: ='3. Term Frequency (TF)'!H14 * $B14 | I14: ='3. Term Frequency (TF)'!I14 * $B14 | J14: ='3. Term Frequency (TF)'!J14 * $B14 | ... Q14: ='3. Term Frequency (TF)'!Q14 * $B14
A15: aset | B15: =LN((15+1)/('3. Term Frequency (TF)'!B15+1))+1 | C15: ='3. Term Frequency (TF)'!C15 * $B15 | D15: ='3. Term Frequency (TF)'!D15 * $B15 | E15: ='3. Term Frequency (TF)'!E15 * $B15 | F15: ='3. Term Frequency (TF)'!F15 * $B15 | G15: ='3. Term Frequency (TF)'!G15 * $B15 | H15: ='3. Term Frequency (TF)'!H15 * $B15 | I15: ='3. Term Frequency (TF)'!I15 * $B15 | J15: ='3. Term Frequency (TF)'!J15 * $B15 | ... Q15: ='3. Term Frequency (TF)'!Q15 * $B15
... A93: wireframing | B93: =LN((15+1)/('3. Term Frequency (TF)'!B93+1))+1 | C93: ='3. Term Frequency (TF)'!C93 * $B93 | D93: ='3. Term Frequency (TF)'!D93 * $B93 | E93: ='3. Term Frequency (TF)'!E93 * $B93 | F93: ='3. Term Frequency (TF)'!F93 * $B93 | G93: ='3. Term Frequency (TF)'!G93 * $B93 | H93: ='3. Term Frequency (TF)'!H93 * $B93 | I93: ='3. Term Frequency (TF)'!I93 * $B93 | J93: ='3. Term Frequency (TF)'!J93 * $B93 | ... Q93: ='3. Term Frequency (TF)'!Q93 * $B93

Sheet 5. Hasil Kemiripan
A1: Kalkulasi Cosine Similarity & Matriks Akhir
A3: Kombinasi | B3: Lowongan | C3: Profil | D3: Dot Product (A•B) | E3: ||A|| | F3: ||B|| | G3: Cosine | H3: Persentase (%)
A4: L1 - P1 | B4: L1 | C4: P1 | D4: =SUMPRODUCT('4. TF-IDF'!C$4:C$93, '4. TF-IDF'!H$4:H$93) | E4: =SQRT(SUMSQ('4. TF-IDF'!C$4:C$93)) | F4: =SQRT(SUMSQ('4. TF-IDF'!H$4:H$93)) | G4: =IF(OR(E4=0, F4=0), 0, D4/(E4*F4)) | H4: =G4
A5: L1 - P2 | B5: L1 | C5: P2 | D5: =SUMPRODUCT('4. TF-IDF'!C$4:C$93, '4. TF-IDF'!I$4:I$93) | E5: =SQRT(SUMSQ('4. TF-IDF'!C$4:C$93)) | F5: =SQRT(SUMSQ('4. TF-IDF'!I$4:I$93)) | G5: =IF(OR(E5=0, F5=0), 0, D5/(E5*F5)) | H5: =G5
A6: L1 - P3 | B6: L1 | C6: P3 | D6: =SUMPRODUCT('4. TF-IDF'!C$4:C$93, '4. TF-IDF'!J$4:J$93) | E6: =SQRT(SUMSQ('4. TF-IDF'!C$4:C$93)) | F6: =SQRT(SUMSQ('4. TF-IDF'!J$4:J$93)) | G6: =IF(OR(E6=0, F6=0), 0, D6/(E6*F6)) | H6: =G6
A7: L1 - P4 | B7: L1 | C7: P4 | D7: =SUMPRODUCT('4. TF-IDF'!C$4:C$93, '4. TF-IDF'!K$4:K$93) | E7: =SQRT(SUMSQ('4. TF-IDF'!C$4:C$93)) | F7: =SQRT(SUMSQ('4. TF-IDF'!K$4:K$93)) | G7: =IF(OR(E7=0, F7=0), 0, D7/(E7*F7)) | H7: =G7
A8: L1 - P5 | B8: L1 | C8: P5 | D8: =SUMPRODUCT('4. TF-IDF'!C$4:C$93, '4. TF-IDF'!L$4:L$93) | E8: =SQRT(SUMSQ('4. TF-IDF'!C$4:C$93)) | F8: =SQRT(SUMSQ('4. TF-IDF'!L$4:L$93)) | G8: =IF(OR(E8=0, F8=0), 0, D8/(E8*F8)) | H8: =G8
A9: L1 - P6 | B9: L1 | C9: P6 | D9: =SUMPRODUCT('4. TF-IDF'!C$4:C$93, '4. TF-IDF'!M$4:M$93) | E9: =SQRT(SUMSQ('4. TF-IDF'!C$4:C$93)) | F9: =SQRT(SUMSQ('4. TF-IDF'!M$4:M$93)) | G9: =IF(OR(E9=0, F9=0), 0, D9/(E9*F9)) | H9: =G9
A10: L1 - P7 | B10: L1 | C10: P7 | D10: =SUMPRODUCT('4. TF-IDF'!C$4:C$93, '4. TF-IDF'!N$4:N$93) | E10: =SQRT(SUMSQ('4. TF-IDF'!C$4:C$93)) | F10: =SQRT(SUMSQ('4. TF-IDF'!N$4:N$93)) | G10: =IF(OR(E10=0, F10=0), 0, D10/(E10*F10)) | H10: =G10
A11: L1 - P8 | B11: L1 | C11: P8 | D11: =SUMPRODUCT('4. TF-IDF'!C$4:C$93, '4. TF-IDF'!O$4:O$93) | E11: =SQRT(SUMSQ('4. TF-IDF'!C$4:C$93)) | F11: =SQRT(SUMSQ('4. TF-IDF'!O$4:O$93)) | G11: =IF(OR(E11=0, F11=0), 0, D11/(E11*F11)) | H11: =G11
A12: L1 - P9 | B12: L1 | C12: P9 | D12: =SUMPRODUCT('4. TF-IDF'!C$4:C$93, '4. TF-IDF'!P$4:P$93) | E12: =SQRT(SUMSQ('4. TF-IDF'!C$4:C$93)) | F12: =SQRT(SUMSQ('4. TF-IDF'!P$4:P$93)) | G12: =IF(OR(E12=0, F12=0), 0, D12/(E12*F12)) | H12: =G12
A13: L1 - P10 | B13: L1 | C13: P10 | D13: =SUMPRODUCT('4. TF-IDF'!C$4:C$93, '4. TF-IDF'!Q$4:Q$93) | E13: =SQRT(SUMSQ('4. TF-IDF'!C$4:C$93)) | F13: =SQRT(SUMSQ('4. TF-IDF'!Q$4:Q$93)) | G13: =IF(OR(E13=0, F13=0), 0, D13/(E13*F13)) | H13: =G13
A14: L2 - P1 | B14: L2 | C14: P1 | D14: =SUMPRODUCT('4. TF-IDF'!D$4:D$93, '4. TF-IDF'!H$4:H$93) | E14: =SQRT(SUMSQ('4. TF-IDF'!D$4:D$93)) | F14: =SQRT(SUMSQ('4. TF-IDF'!H$4:H$93)) | G14: =IF(OR(E14=0, F14=0), 0, D14/(E14*F14)) | H14: =G14
A15: L2 - P2 | B15: L2 | C15: P2 | D15: =SUMPRODUCT('4. TF-IDF'!D$4:D$93, '4. TF-IDF'!I$4:I$93) | E15: =SQRT(SUMSQ('4. TF-IDF'!D$4:D$93)) | F15: =SQRT(SUMSQ('4. TF-IDF'!I$4:I$93)) | G15: =IF(OR(E15=0, F15=0), 0, D15/(E15*F15)) | H15: =G15
A16: L2 - P3 | B16: L2 | C16: P3 | D16: =SUMPRODUCT('4. TF-IDF'!D$4:D$93, '4. TF-IDF'!J$4:J$93) | E16: =SQRT(SUMSQ('4. TF-IDF'!D$4:D$93)) | F16: =SQRT(SUMSQ('4. TF-IDF'!J$4:J$93)) | G16: =IF(OR(E16=0, F16=0), 0, D16/(E16*F16)) | H16: =G16
A17: L2 - P4 | B17: L2 | C17: P4 | D17: =SUMPRODUCT('4. TF-IDF'!D$4:D$93, '4. TF-IDF'!K$4:K$93) | E17: =SQRT(SUMSQ('4. TF-IDF'!D$4:D$93)) | F17: =SQRT(SUMSQ('4. TF-IDF'!K$4:K$93)) | G17: =IF(OR(E17=0, F17=0), 0, D17/(E17*F17)) | H17: =G17
A18: L2 - P5 | B18: L2 | C18: P5 | D18: =SUMPRODUCT('4. TF-IDF'!D$4:D$93, '4. TF-IDF'!L$4:L$93) | E18: =SQRT(SUMSQ('4. TF-IDF'!D$4:D$93)) | F18: =SQRT(SUMSQ('4. TF-IDF'!L$4:L$93)) | G18: =IF(OR(E18=0, F18=0), 0, D18/(E18*F18)) | H18: =G18
A19: L2 - P6 | B19: L2 | C19: P6 | D19: =SUMPRODUCT('4. TF-IDF'!D$4:D$93, '4. TF-IDF'!M$4:M$93) | E19: =SQRT(SUMSQ('4. TF-IDF'!D$4:D$93)) | F19: =SQRT(SUMSQ('4. TF-IDF'!M$4:M$93)) | G19: =IF(OR(E19=0, F19=0), 0, D19/(E19*F19)) | H19: =G19
A20: L2 - P7 | B20: L2 | C20: P7 | D20: =SUMPRODUCT('4. TF-IDF'!D$4:D$93, '4. TF-IDF'!N$4:N$93) | E20: =SQRT(SUMSQ('4. TF-IDF'!D$4:D$93)) | F20: =SQRT(SUMSQ('4. TF-IDF'!N$4:N$93)) | G20: =IF(OR(E20=0, F20=0), 0, D20/(E20*F20)) | H20: =G20
A21: L2 - P8 | B21: L2 | C21: P8 | D21: =SUMPRODUCT('4. TF-IDF'!D$4:D$93, '4. TF-IDF'!O$4:O$93) | E21: =SQRT(SUMSQ('4. TF-IDF'!D$4:D$93)) | F21: =SQRT(SUMSQ('4. TF-IDF'!O$4:O$93)) | G21: =IF(OR(E21=0, F21=0), 0, D21/(E21*F21)) | H21: =G21
A22: L2 - P9 | B22: L2 | C22: P9 | D22: =SUMPRODUCT('4. TF-IDF'!D$4:D$93, '4. TF-IDF'!P$4:P$93) | E22: =SQRT(SUMSQ('4. TF-IDF'!D$4:D$93)) | F22: =SQRT(SUMSQ('4. TF-IDF'!P$4:P$93)) | G22: =IF(OR(E22=0, F22=0), 0, D22/(E22*F22)) | H22: =G22
A23: L2 - P10 | B23: L2 | C23: P10 | D23: =SUMPRODUCT('4. TF-IDF'!D$4:D$93, '4. TF-IDF'!Q$4:Q$93) | E23: =SQRT(SUMSQ('4. TF-IDF'!D$4:D$93)) | F23: =SQRT(SUMSQ('4. TF-IDF'!Q$4:Q$93)) | G23: =IF(OR(E23=0, F23=0), 0, D23/(E23*F23)) | H23: =G23
A24: L3 - P1 | B24: L3 | C24: P1 | D24: =SUMPRODUCT('4. TF-IDF'!E$4:E$93, '4. TF-IDF'!H$4:H$93) | E24: =SQRT(SUMSQ('4. TF-IDF'!E$4:E$93)) | F24: =SQRT(SUMSQ('4. TF-IDF'!H$4:H$93)) | G24: =IF(OR(E24=0, F24=0), 0, D24/(E24*F24)) | H24: =G24
A25: L3 - P2 | B25: L3 | C25: P2 | D25: =SUMPRODUCT('4. TF-IDF'!E$4:E$93, '4. TF-IDF'!I$4:I$93) | E25: =SQRT(SUMSQ('4. TF-IDF'!E$4:E$93)) | F25: =SQRT(SUMSQ('4. TF-IDF'!I$4:I$93)) | G25: =IF(OR(E25=0, F25=0), 0, D25/(E25*F25)) | H25: =G25
A26: L3 - P3 | B26: L3 | C26: P3 | D26: =SUMPRODUCT('4. TF-IDF'!E$4:E$93, '4. TF-IDF'!J$4:J$93) | E26: =SQRT(SUMSQ('4. TF-IDF'!E$4:E$93)) | F26: =SQRT(SUMSQ('4. TF-IDF'!J$4:J$93)) | G26: =IF(OR(E26=0, F26=0), 0, D26/(E26*F26)) | H26: =G26
A27: L3 - P4 | B27: L3 | C27: P4 | D27: =SUMPRODUCT('4. TF-IDF'!E$4:E$93, '4. TF-IDF'!K$4:K$93) | E27: =SQRT(SUMSQ('4. TF-IDF'!E$4:E$93)) | F27: =SQRT(SUMSQ('4. TF-IDF'!K$4:K$93)) | G27: =IF(OR(E27=0, F27=0), 0, D27/(E27*F27)) | H27: =G27
A28: L3 - P5 | B28: L3 | C28: P5 | D28: =SUMPRODUCT('4. TF-IDF'!E$4:E$93, '4. TF-IDF'!L$4:L$93) | E28: =SQRT(SUMSQ('4. TF-IDF'!E$4:E$93)) | F28: =SQRT(SUMSQ('4. TF-IDF'!L$4:L$93)) | G28: =IF(OR(E28=0, F28=0), 0, D28/(E28*F28)) | H28: =G28
A29: L3 - P6 | B29: L3 | C29: P6 | D29: =SUMPRODUCT('4. TF-IDF'!E$4:E$93, '4. TF-IDF'!M$4:M$93) | E29: =SQRT(SUMSQ('4. TF-IDF'!E$4:E$93)) | F29: =SQRT(SUMSQ('4. TF-IDF'!M$4:M$93)) | G29: =IF(OR(E29=0, F29=0), 0, D29/(E29*F29)) | H29: =G29
A30: L3 - P7 | B30: L3 | C30: P7 | D30: =SUMPRODUCT('4. TF-IDF'!E$4:E$93, '4. TF-IDF'!N$4:N$93) | E30: =SQRT(SUMSQ('4. TF-IDF'!E$4:E$93)) | F30: =SQRT(SUMSQ('4. TF-IDF'!N$4:N$93)) | G30: =IF(OR(E30=0, F30=0), 0, D30/(E30*F30)) | H30: =G30
A31: L3 - P8 | B31: L3 | C31: P8 | D31: =SUMPRODUCT('4. TF-IDF'!E$4:E$93, '4. TF-IDF'!O$4:O$93) | E31: =SQRT(SUMSQ('4. TF-IDF'!E$4:E$93)) | F31: =SQRT(SUMSQ('4. TF-IDF'!O$4:O$93)) | G31: =IF(OR(E31=0, F31=0), 0, D31/(E31*F31)) | H31: =G31
A32: L3 - P9 | B32: L3 | C32: P9 | D32: =SUMPRODUCT('4. TF-IDF'!E$4:E$93, '4. TF-IDF'!P$4:P$93) | E32: =SQRT(SUMSQ('4. TF-IDF'!E$4:E$93)) | F32: =SQRT(SUMSQ('4. TF-IDF'!P$4:P$93)) | G32: =IF(OR(E32=0, F32=0), 0, D32/(E32*F32)) | H32: =G32
A33: L3 - P10 | B33: L3 | C33: P10 | D33: =SUMPRODUCT('4. TF-IDF'!E$4:E$93, '4. TF-IDF'!Q$4:Q$93) | E33: =SQRT(SUMSQ('4. TF-IDF'!E$4:E$93)) | F33: =SQRT(SUMSQ('4. TF-IDF'!Q$4:Q$93)) | G33: =IF(OR(E33=0, F33=0), 0, D33/(E33*F33)) | H33: =G33
A34: L4 - P1 | B34: L4 | C34: P1 | D34: =SUMPRODUCT('4. TF-IDF'!F$4:F$93, '4. TF-IDF'!H$4:H$93) | E34: =SQRT(SUMSQ('4. TF-IDF'!F$4:F$93)) | F34: =SQRT(SUMSQ('4. TF-IDF'!H$4:H$93)) | G34: =IF(OR(E34=0, F34=0), 0, D34/(E34*F34)) | H34: =G34
A35: L4 - P2 | B35: L4 | C35: P2 | D35: =SUMPRODUCT('4. TF-IDF'!F$4:F$93, '4. TF-IDF'!I$4:I$93) | E35: =SQRT(SUMSQ('4. TF-IDF'!F$4:F$93)) | F35: =SQRT(SUMSQ('4. TF-IDF'!I$4:I$93)) | G35: =IF(OR(E35=0, F35=0), 0, D35/(E35*F35)) | H35: =G35
A36: L4 - P3 | B36: L4 | C36: P3 | D36: =SUMPRODUCT('4. TF-IDF'!F$4:F$93, '4. TF-IDF'!J$4:J$93) | E36: =SQRT(SUMSQ('4. TF-IDF'!F$4:F$93)) | F36: =SQRT(SUMSQ('4. TF-IDF'!J$4:J$93)) | G36: =IF(OR(E36=0, F36=0), 0, D36/(E36*F36)) | H36: =G36
A37: L4 - P4 | B37: L4 | C37: P4 | D37: =SUMPRODUCT('4. TF-IDF'!F$4:F$93, '4. TF-IDF'!K$4:K$93) | E37: =SQRT(SUMSQ('4. TF-IDF'!F$4:F$93)) | F37: =SQRT(SUMSQ('4. TF-IDF'!K$4:K$93)) | G37: =IF(OR(E37=0, F37=0), 0, D37/(E37*F37)) | H37: =G37
A38: L4 - P5 | B38: L4 | C38: P5 | D38: =SUMPRODUCT('4. TF-IDF'!F$4:F$93, '4. TF-IDF'!L$4:L$93) | E38: =SQRT(SUMSQ('4. TF-IDF'!F$4:F$93)) | F38: =SQRT(SUMSQ('4. TF-IDF'!L$4:L$93)) | G38: =IF(OR(E38=0, F38=0), 0, D38/(E38*F38)) | H38: =G38
A39: L4 - P6 | B39: L4 | C39: P6 | D39: =SUMPRODUCT('4. TF-IDF'!F$4:F$93, '4. TF-IDF'!M$4:M$93) | E39: =SQRT(SUMSQ('4. TF-IDF'!F$4:F$93)) | F39: =SQRT(SUMSQ('4. TF-IDF'!M$4:M$93)) | G39: =IF(OR(E39=0, F39=0), 0, D39/(E39*F39)) | H39: =G39
A40: L4 - P7 | B40: L4 | C40: P7 | D40: =SUMPRODUCT('4. TF-IDF'!F$4:F$93, '4. TF-IDF'!N$4:N$93) | E40: =SQRT(SUMSQ('4. TF-IDF'!F$4:F$93)) | F40: =SQRT(SUMSQ('4. TF-IDF'!N$4:N$93)) | G40: =IF(OR(E40=0, F40=0), 0, D40/(E40*F40)) | H40: =G40
A41: L4 - P8 | B41: L4 | C41: P8 | D41: =SUMPRODUCT('4. TF-IDF'!F$4:F$93, '4. TF-IDF'!O$4:O$93) | E41: =SQRT(SUMSQ('4. TF-IDF'!F$4:F$93)) | F41: =SQRT(SUMSQ('4. TF-IDF'!O$4:O$93)) | G41: =IF(OR(E41=0, F41=0), 0, D41/(E41*F41)) | H41: =G41
...
